Workbook

Sheet Munka1
B1: Cikkszám | C1: FNév | D1: Kiszerelés (ml) | E1: Ár | F1: Szín
B2: A0001 | C2: Fehér Arany | D2: 100000 | E2: =E3*10 -> 300000 | F2: Fehér
B3: A0002 | C3: Fehér Arany | D3: 10000 | E3: =E4*10-E4 -> 30000 | F3: Fehér
B4: A0003 | C4: Fehér Arany | D4: 1000 | E4: =E5/0.75 -> 3333.3333 | F4: Fehér
B5: A0004 | C5: Fehér Arany | D5: 750 | E5: =Munka2!C2 -> 2500 | F5: Fehér
B6: A0005 | C6: Fehér Arany | D6: 500 | E6: =(E4-(E4/10))/2 -> 1500 | F6: Fehér
B7: A0006 | C7: Fehér Arany | D7: 300 | E7: =(E4-(E4/10))/3 -> 1000 | F7: Fehér
B8: A0007 | C8: Fehér Arany | D8: 100 | E8: =E4/10 -> 333.33333 | F8: Fehér
B9: A0008 | C9: Fehér Arany | D9: 10 | E9: =E8/10 -> 33.333333 | F9: Fehér
B10: A0009 | C10: Fehér Arany | D10: 1 | E10: =E9/10 -> 3.3333333 | F10: Fehér
B11: A0010 | C11: Vörös Rezes | D11: 100000 | E11: =E12*10 -> 216000 | F11: Vörös
B12: A0011 | C12: Vörös Rezes | D12: 10000 | E12: =E13*10-E13 -> 21600 | F12: Vörös
B13: A0012 | C13: Vörös Rezes | D13: 1000 | E13: =E14/0.75 -> 2400 | F13: Vörös
B14: A0013 | C14: Vörös Rezes | D14: 750 | E14: =Munka2!C3 -> 1800 | F14: Vörös
B15: A0014 | C15: Vörös Rezes | D15: 500 | E15: =(E13-(E13/10))/2 -> 1080 | F15: Vörös
B16: A0015 | C16: Vörös Rezes | D16: 300 | E16: =(E13-(E13/10))/3 -> 720 | F16: Vörös
B17: A0016 | C17: Vörös Rezes | D17: 100 | E17: =E13/10 -> 240 | F17: Vörös
B18: A0017 | C18: Vörös Rezes | D18: 10 | E18: =E17/10 -> 24 | F18: Vörös
B19: A0018 | C19: Vörös Rezes | D19: 1 | E19: =E18/10 -> 2.4 | F19: Vörös
B20: A0019 | C20: Rozé Rózsája | D20: 100000 | E20: =E21*10 -> 240000 | F20: Rozé
B21: A0020 | C21: Rozé Rózsája | D21: 10000 | E21: =E22*10-E22 -> 24000 | F21: Rozé
B22: A0021 | C22: Rozé Rózsája | D22: 1000 | E22: =E23/0.75 -> 2666.6667 | F22: Rozé
B23: A0022 | C23: Rozé Rózsája | D23: 750 | E23: =Munka2!C4 -> 2000 | F23: Rozé
B24: A0023 | C24: Rozé Rózsája | D24: 500 | E24: =(E22-(E22/10))/2 -> 1200 | F24: Rozé
B25: A0024 | C25: Rozé Rózsája | D25: 300 | E25: =(E22-(E22/10))/3 -> 800 | F25: Rozé
B26: A0025 | C26: Rozé Rózsája | D26: 100 | E26: =E22/10 -> 266.66667 | F26: Rozé
B27: A0026 | C27: Rozé Rózsája | D27: 10 | E27: =E26/10 -> 26.666667 | F27: Rozé
B28: A0027 | C28: Rozé Rózsája | D28: 1 | E28: =E27/10 -> 2.6666667 | F28: Rozé
B29: A0028 | C29: Józsi bácsi Koccintós | D29: 100000 | E29: =E30*10 -> 108000 | F29: Vegyes
B30: A0029 | C30: Józsi bácsi Koccintós | D30: 10000 | E30: =E31*10-E31 -> 10800 | F30: Vegyes
B31: A0030 | C31: Józsi bácsi Koccintós | D31: 1000 | E31: =E32/0.75 -> 1200 | F31: Vegyes
B32: A0031 | C32: Józsi bácsi Koccintós | D32: 750 | E32: =Munka2!C5 -> 900 | F32: Vegyes
B33: A0032 | C33: Józsi bácsi Koccintós | D33: 500 | E33: =(E31-(E31/10))/2 -> 540 | F33: Vegyes
B34: A0033 | C34: Józsi bácsi Koccintós | D34: 300 | E34: =(E31-(E31/10))/3 -> 360 | F34: Vegyes
B35: A0034 | C35: Józsi bácsi Koccintós | D35: 100 | E35: =E31/10 -> 120 | F35: Vegyes
B36: A0035 | C36: Józsi bácsi Koccintós | D36: 10 | E36: =E35/10 -> 12 | F36: Vegyes
B37: A0036 | C37: Józsi bácsi Koccintós | D37: 1 | E37: =E36/10 -> 1.2 | F37: Vegyes
B38: A0037 | C38: Don Perignon | D38: 100000 | E38: =E39*10 -> 11998800 | F38: Pezsgő
B39: A0038 | C39: Don Perignon | D39: 10000 | E39: =E40*10-E40 -> 1199880 | F39: Pezsgő
B40: A0039 | C40: Don Perignon | D40: 1000 | E40: =E41/0.75 -> 133320 | F40: Pezsgő
...

Sheet Munka2
B2: Fehér Arany | C2: 2500
B3: Vörös Rezes | C3: 1800
B4: Rozé Rózsája | C4: 2000
B5: Józsi bácsi Koccintós | C5: 900
B6: Don Perignon | C6: 99990
B7: Trockenbeerenauslese | C7: 2720000
B8: 2007-es Birtok Eszencia | C8: 492000
B9: NEIDDMEGBOR | C9: 90
